{
 "cells": [
  {
   "cell_type": "markdown",
   "id": "a94abd6d-9c32-4429-8c05-dc4d4260fb92",
   "metadata": {},
   "source": [
    "# Object Detection using OpenCV"
   ]
  },
  {
   "cell_type": "code",
   "execution_count": 1,
   "id": "e3ad6190-0624-43f3-beff-7ab0972dd5e0",
   "metadata": {},
   "outputs": [],
   "source": [
    "# Importing some importatnt libraries\n",
    "import cv2\n",
    "import matplotlib.pyplot as plt"
   ]
  },
  {
   "cell_type": "code",
   "execution_count": 2,
   "id": "09d34422-6c2b-4e15-9f85-4847f68731e2",
   "metadata": {},
   "outputs": [],
   "source": [
    "config_file = 'ssd_mobilenet_v3_large_coco_2020_01_14.pbtext'\n",
    "frozen_model = 'frozen_inference_graph.pb'"
   ]
  },
  {
   "cell_type": "code",
   "execution_count": 3,
   "id": "c0cd1fe7-797f-4525-b596-bd0d08788b3c",
   "metadata": {},
   "outputs": [
    {
     "ename": "SystemError",
     "evalue": "<class 'cv2.dnn.DetectionModel'> returned a result with an exception set",
     "output_type": "error",
     "traceback": [
      "\u001b[1;31m---------------------------------------------------------------------------\u001b[0m",
      "\u001b[1;31merror\u001b[0m                                     Traceback (most recent call last)",
      "\u001b[1;31merror\u001b[0m: OpenCV(4.9.0) D:\\a\\opencv-python\\opencv-python\\opencv\\modules\\dnn\\src\\caffe\\caffe_io.cpp:1126: error: (-2:Unspecified error) FAILED: fs.is_open(). Can't open \"ssd_mobilenet_v3_large_coco_2020_01_14.pbtext\" in function 'cv::dnn::ReadProtoFromTextFile'\n",
      "\nThe above exception was the direct cause of the following exception:\n",
      "\u001b[1;31mSystemError\u001b[0m                               Traceback (most recent call last)",
      "Cell \u001b[1;32mIn[3], line 2\u001b[0m\n\u001b[0;32m      1\u001b[0m \u001b[38;5;66;03m# Creating Model\u001b[39;00m\n\u001b[1;32m----> 2\u001b[0m model \u001b[38;5;241m=\u001b[39m \u001b[43mcv2\u001b[49m\u001b[38;5;241;43m.\u001b[39;49m\u001b[43mdnn_DetectionModel\u001b[49m\u001b[43m(\u001b[49m\u001b[43mfrozen_model\u001b[49m\u001b[43m,\u001b[49m\u001b[43mconfig_file\u001b[49m\u001b[43m)\u001b[49m\n",
      "\u001b[1;31mSystemError\u001b[0m: <class 'cv2.dnn.DetectionModel'> returned a result with an exception set"
     ]
    }
   ],
   "source": [
    "# Creating Model\n",
    "model = cv2.dnn_DetectionModel(frozen_model,config_file)"
   ]
  },
  {
   "cell_type": "code",
   "execution_count": null,
   "id": "07c4e044-3508-42f2-ac63-4eade864f57b",
   "metadata": {},
   "outputs": [],
   "source": []
  }
 ],
 "metadata": {
  "kernelspec": {
   "display_name": "Python 3 (ipykernel)",
   "language": "python",
   "name": "python3"
  },
  "language_info": {
   "codemirror_mode": {
    "name": "ipython",
    "version": 3
   },
   "file_extension": ".py",
   "mimetype": "text/x-python",
   "name": "python",
   "nbconvert_exporter": "python",
   "pygments_lexer": "ipython3",
   "version": "3.11.9"
  }
 },
 "nbformat": 4,
 "nbformat_minor": 5
}
